Workbook

Sheet Master Roster
A1: Science&Math Camp R315&408 | E1: Language Camp R304&305 | I1: Teachers
A2: HR-LK Math-Richard Physics-Keda Bio-Jenny Chem-Cooper | E2: HR-Christine/Talia English-Summer/Julie | I2: KeDa
A3: 序号No. | B3: 姓名 Name | C3: 年级 Grade Level | E3: 序号No. | F3: 姓名 Name | G3: 年级 Grade Level | I3: Cooper
A4: 1 | B4: 古雨轩 Nancy | C4: G5 | E4: 1 | F4: 刘知行 Ballie | G4: G8 | I4: Tank
A5: 2 | B5: 泓仓·丹增巴桑Kriss | C5: G5 | E5: 2 | F5: 于海晨 Harrison | G5: G9 | I5: Jenny
A6: 3 | B6: 胡景覃 Jacques | C6: G6 | D6: 。 | E6: 3 | F6: 胡清源 Lucas | G6: G9 | I6: Richard
A7: 4 | B7: 谢逸生 Mandy | C7: G6 | E7: 4 | F7: 刘信杰 Jerry | G7: G9 | I7: Summer
A8: 5 | B8: 张哲燃 Ethan | C8: G6 | E8: 5 | F8: 吴佳兴 Owen | G8: G9 | I8: Julie
A9: 6 | B9: 朱航舟 Tim Zhou | C9: G6 | E9: 6 | F9: 王震言 Wayne | G9: G9 | I9: Jiao
A10: 7 | B10: 吴奕澄 Leo | C10: G6A | E10: 7 | F10: 陈翼 Eden | G10: G9
A11: 8 | B11: 宋昱呈 Austin | C11: G6A | E11: 8 | F11: 舒诗涵 Sonnet | G11: G9
A12: 9 | B12: 黄晓帅 Neo | C12: G6A | E12: 9 | F12: 徐媛媛 Lucky | G12: G9
A13: 10 | B13: 曲国宇 Quincy | C13: G6B | E13: 10 | F13: 李思源 Philip | G13: G10
A14: 11 | B14: 余金武 Tim Yu | C14: G6B | E14: 11 | F14: 刘芷鸢 Iris | G14: G10
A15: 12 | B15: 祁骁汉 Shawn | C15: G6B | E15: 12 | F15: 黄薇扬 Camille | G15: G10
A16: 13 | B16: 童浩 Sunny | C16: G6C | E16: 13 | F16: 刘嘉琪 Angel | G16: G11
A17: 14 | B17: 范奕之 Alisa | C17: G7 | E17: 14 | F17: 张莹菲儿 Phoebe | G17: G11
A18: 15 | B18: 刘俊熙 Junxi | C18: G7 | E18: 15 | F18: 谢润墨 Jason | G18: G11
A19: 16 | B19: 董佳琦 Lucy Dong | C19: G7 | E19: 16 | F19: 周睿一stephennie | G19: G9
A20: 17 | B20: 陈飞霖 Felix | C20: G7
A21: 18 | B21: 廖小迪 Shirley | C21: G7
A22: 19 | B22: 袁尽唯 Lucy Yuan | C22: G7
A23: 20 | B23: 薛宏浚 Alan | C23: G7B
A24: 21 | B24: 周宇恒 Lucas | C24: G8
A25: 22 | B25: 任潇然 Ryan | C25: G8
A26: 23 | B26: 周予馨 Cindy | C26: G8
A27: 24 | B27: 齐屿轩 Susan | C27: G8
A28: 25 | B28: 雷欣玥 Moon | C28: G8
A29: 26 | B29: 张慧娜 Anna | C29: G8
A30: 27 | B30: 罗寅 Abel | C30: G8

Sheet 📄LeaderBoard
A1: Summer Camp House Leaderboard | G1: NOTE: Ensure the student names in each teacher sheet is exactly the same as the student names in the respective houses, otherwise the points won't add up.
A2: Days | B2: Pythagoras | C2: Tesla | D2: Einstein | E2: Darwin
A3: 1 | B3: ==IFERROR(SUMPRODUCT(ISNUMBER(SEARCH(B$2,KeDa!$D$4:$D$100))*IFERROR(KeDa!$E$4:$K$100,0)),0)+IFERROR(SUMPRODUCT(ISNUMBER(SEARCH(B$2,Tank!$D$4:$D$100))*IFERROR(Tank!$E$4:$K$100,0)),0)+IFERROR(SUMPRODUCT(ISNUMBER(SEARCH(B$2,Richard!$D$4:$D$100))*IFERROR(Richard!$E$4:$K$100,0)),0)+IFERROR(SUMPRODUCT(ISNUMBER(SEARCH(B$2,Jenny!$D$4:$D$100))*IFERROR(Jenny!$E$4:$K$100,0)),0)+IFERROR(SUMPRODUCT(ISNUMBER(SEARCH(B$2,Cooper!$D$4:$D$100))*IFERROR(Cooper!$E$4:$K$100,0)),0)+IFERROR(SUMPRODUCT(ISNUMBER(SEARCH(B$2,Summer!$D$4:$D$100))*IFERROR(Summer!$E$4:$K$100,0)),0)+IFERROR(SUMPRODUCT(ISNUMBER(SEARCH(B$2,Julie!$D$4:$D$100))*IFERROR(Julie!$E$4:$K$100,0)),0)+IFERROR(SUMPRODUCT(ISNUMBER(SEARCH(B$2,Jiao!$D$4:$D$100))*IFERROR(Jiao!$E$4:$K$100,0)),0) | C3: ==IFERROR(SUMPRODUCT(ISNUMBER(SEARCH(C$2,KeDa!$D$4:$D$100))*IFERROR(KeDa!$E$4:$K$100,0)),0)+IFERROR(SUMPRODUCT(ISNUMBER(SEARCH(C$2,Tank!$D$4:$D$100))*IFERROR(Tank!$E$4:$K$100,0)),0)+IFERROR(SUMPRODUCT(ISNUMBER(SEARCH(C$2,Richard!$D$4:$D$100))*IFERROR(Richard!$E$4:$K$100,0)),0)+IFERROR(SUMPRODUCT(ISNUMBER(SEARCH(C$2,Jenny!$D$4:$D$100))*IFERROR(Jenny!$E$4:$K$100,0)),0)+IFERROR(SUMPRODUCT(ISNUMBER(SEARCH(C$2,Cooper!$D$4:$D$100))*IFERROR(Cooper!$E$4:$K$100,0)),0)+IFERROR(SUMPRODUCT(ISNUMBER(SEARCH(C$2,Summer!$D$4:$D$100))*IFERROR(Summer!$E$4:$K$100,0)),0)+IFERROR(SUMPRODUCT(ISNUMBER(SEARCH(C$2,Julie!$D$4:$D$100))*IFERROR(Julie!$E$4:$K$100,0)),0)+IFERROR(SUMPRODUCT(ISNUMBER(SEARCH(C$2,Jiao!$D$4:$D$100))*IFERROR(Jiao!$E$4:$K$100,0)),0) | D3: ==IFERROR(SUMPRODUCT(ISNUMBER(SEARCH(D$2,KeDa!$D$4:$D$100))*IFERROR(KeDa!$E$4:$K$100,0)),0)+IFERROR(SUMPRODUCT(ISNUMBER(SEARCH(D$2,Tank!$D$4:$D$100))*IFERROR(Tank!$E$4:$K$100,0)),0)+IFERROR(SUMPRODUCT(ISNUMBER(SEARCH(D$2,Richard!$D$4:$D$100))*IFERROR(Richard!$E$4:$K$100,0)),0)+IFERROR(SUMPRODUCT(ISNUMBER(SEARCH(D$2,Jenny!$D$4:$D$100))*IFERROR(Jenny!$E$4:$K$100,0)),0)+IFERROR(SUMPRODUCT(ISNUMBER(SEARCH(D$2,Cooper!$D$4:$D$100))*IFERROR(Cooper!$E$4:$K$100,0)),0)+IFERROR(SUMPRODUCT(ISNUMBER(SEARCH(D$2,Summer!$D$4:$D$100))*IFERROR(Summer!$E$4:$K$100,0)),0)+IFERROR(SUMPRODUCT(ISNUMBER(SEARCH(D$2,Julie!$D$4:$D$100))*IFERROR(Julie!$E$4:$K$100,0)),0)+IFERROR(SUMPRODUCT(ISNUMBER(SEARCH(D$2,Jiao!$D$4:$D$100))*IFERROR(Jiao!$E$4:$K$100,0)),0) | E3: ==IFERROR(SUMPRODUCT(ISNUMBER(SEARCH(E$2,KeDa!$D$4:$D$100))*IFERROR(KeDa!$E$4:$K$100,0)),0)+IFERROR(SUMPRODUCT(ISNUMBER(SEARCH(E$2,Tank!$D$4:$D$100))*IFERROR(Tank!$E$4:$K$100,0)),0)+IFERROR(SUMPRODUCT(ISNUMBER(SEARCH(E$2,Richard!$D$4:$D$100))*IFERROR(Richard!$E$4:$K$100,0)),0)+IFERROR(SUMPRODUCT(ISNUMBER(SEARCH(E$2,Jenny!$D$4:$D$100))*IFERROR(Jenny!$E$4:$K$100,0)),0)+IFERROR(SUMPRODUCT(ISNUMBER(SEARCH(E$2,Cooper!$D$4:$D$100))*IFERROR(Cooper!$E$4:$K$100,0)),0)+IFERROR(SUMPRODUCT(ISNUMBER(SEARCH(E$2,Summer!$D$4:$D$100))*IFERROR(Summer!$E$4:$K$100,0)),0)+IFERROR(SUMPRODUCT(ISNUMBER(SEARCH(E$2,Julie!$D$4:$D$100))*IFERROR(Julie!$E$4:$K$100,0)),0)+IFERROR(SUMPRODUCT(ISNUMBER(SEARCH(E$2,Jiao!$D$4:$D$100))*IFERROR(Jiao!$E$4:$K$100,0)),0)
A4: 2 | B4: ==IFERROR(SUMPRODUCT(ISNUMBER(SEARCH(B$2,KeDa!$D$4:$D$100))*IFERROR(KeDa!$M$4:$S$100,0)),0)+IFERROR(SUMPRODUCT(ISNUMBER(SEARCH(B$2,Tank!$D$4:$D$100))*IFERROR(Tank!$M$4:$S$100,0)),0)+IFERROR(SUMPRODUCT(ISNUMBER(SEARCH(B$2,Richard!$D$4:$D$100))*IFERROR(Richard!$M$4:$S$100,0)),0)+IFERROR(SUMPRODUCT(ISNUMBER(SEARCH(B$2,Jenny!$D$4:$D$100))*IFERROR(Jenny!$M$4:$S$100,0)),0)+IFERROR(SUMPRODUCT(ISNUMBER(SEARCH(B$2,Cooper!$D$4:$D$100))*IFERROR(Cooper!$M$4:$S$100,0)),0)+IFERROR(SUMPRODUCT(ISNUMBER(SEARCH(B$2,Summer!$D$4:$D$100))*IFERROR(Summer!$M$4:$S$100,0)),0)+IFERROR(SUMPRODUCT(ISNUMBER(SEARCH(B$2,Julie!$D$4:$D$100))*IFERROR(Julie!$M$4:$S$100,0)),0)+IFERROR(SUMPRODUCT(ISNUMBER(SEARCH(B$2,Jiao!$D$4:$D$100))*IFERROR(Jiao!$M$4:$S$100,0)),0) | C4: ==IFERROR(SUMPRODUCT(ISNUMBER(SEARCH(C$2,KeDa!$D$4:$D$100))*IFERROR(KeDa!$M$4:$S$100,0)),0)+IFERROR(SUMPRODUCT(ISNUMBER(SEARCH(C$2,Tank!$D$4:$D$100))*IFERROR(Tank!$M$4:$S$100,0)),0)+IFERROR(SUMPRODUCT(ISNUMBER(SEARCH(C$2,Richard!$D$4:$D$100))*IFERROR(Richard!$M$4:$S$100,0)),0)+IFERROR(SUMPRODUCT(ISNUMBER(SEARCH(C$2,Jenny!$D$4:$D$100))*IFERROR(Jenny!$M$4:$S$100,0)),0)+IFERROR(SUMPRODUCT(ISNUMBER(SEARCH(C$2,Cooper!$D$4:$D$100))*IFERROR(Cooper!$M$4:$S$100,0)),0)+IFERROR(SUMPRODUCT(ISNUMBER(SEARCH(C$2,Summer!$D$4:$D$100))*IFERROR(Summer!$M$4:$S$100,0)),0)+IFERROR(SUMPRODUCT(ISNUMBER(SEARCH(C$2,Julie!$D$4:$D$100))*IFERROR(Julie!$M$4:$S$100,0)),0)+IFERROR(SUMPRODUCT(ISNUMBER(SEARCH(C$2,Jiao!$D$4:$D$100))*IFERROR(Jiao!$M$4:$S$100,0)),0) | D4: ==IFERROR(SUMPRODUCT(ISNUMBER(SEARCH(D$2,KeDa!$D$4:$D$100))*IFERROR(KeDa!$M$4:$S$100,0)),0)+IFERROR(SUMPRODUCT(ISNUMBER(SEARCH(D$2,Tank!$D$4:$D$100))*IFERROR(Tank!$M$4:$S$100,0)),0)+IFERROR(SUMPRODUCT(ISNUMBER(SEARCH(D$2,Richard!$D$4:$D$100))*IFERROR(Richard!$M$4:$S$100,0)),0)+IFERROR(SUMPRODUCT(ISNUMBER(SEARCH(D$2,Jenny!$D$4:$D$100))*IFERROR(Jenny!$M$4:$S$100,0)),0)+IFERROR(SUMPRODUCT(ISNUMBER(SEARCH(D$2,Cooper!$D$4:$D$100))*IFERROR(Cooper!$M$4:$S$100,0)),0)+IFERROR(SUMPRODUCT(ISNUMBER(SEARCH(D$2,Summer!$D$4:$D$100))*IFERROR(Summer!$M$4:$S$100,0)),0)+IFERROR(SUMPRODUCT(ISNUMBER(SEARCH(D$2,Julie!$D$4:$D$100))*IFERROR(Julie!$M$4:$S$100,0)),0)+IFERROR(SUMPRODUCT(ISNUMBER(SEARCH(D$2,Jiao!$D$4:$D$100))*IFERROR(Jiao!$M$4:$S$100,0)),0) | E4: ==IFERROR(SUMPRODUCT(ISNUMBER(SEARCH(E$2,KeDa!$D$4:$D$100))*IFERROR(KeDa!$M$4:$S$100,0)),0)+IFERROR(SUMPRODUCT(ISNUMBER(SEARCH(E$2,Tank!$D$4:$D$100))*IFERROR(Tank!$M$4:$S$100,0)),0)+IFERROR(SUMPRODUCT(ISNUMBER(SEARCH(E$2,Richard!$D$4:$D$100))*IFERROR(Richard!$M$4:$S$100,0)),0)+IFERROR(SUMPRODUCT(ISNUMBER(SEARCH(E$2,Jenny!$D$4:$D$100))*IFERROR(Jenny!$M$4:$S$100,0)),0)+IFERROR(SUMPRODUCT(ISNUMBER(SEARCH(E$2,Cooper!$D$4:$D$100))*IFERROR(Cooper!$M$4:$S$100,0)),0)+IFERROR(SUMPRODUCT(ISNUMBER(SEARCH(E$2,Summer!$D$4:$D$100))*IFERROR(Summer!$M$4:$S$100,0)),0)+IFERROR(SUMPRODUCT(ISNUMBER(SEARCH(E$2,Julie!$D$4:$D$100))*IFERROR(Julie!$M$4:$S$100,0)),0)+IFERROR(SUMPRODUCT(ISNUMBER(SEARCH(E$2,Jiao!$D$4:$D$100))*IFERROR(Jiao!$M$4:$S$100,0)),0)
A5: 3 | B5: ==IFERROR(SUMPRODUCT(ISNUMBER(SEARCH(B$2,KeDa!$D$4:$D$100))*IFERROR(KeDa!$U$4:$AA$100,0)),0)+IFERROR(SUMPRODUCT(ISNUMBER(SEARCH(B$2,Tank!$D$4:$D$100))*IFERROR(Tank!$U$4:$AA$100,0)),0)+IFERROR(SUMPRODUCT(ISNUMBER(SEARCH(B$2,Richard!$D$4:$D$100))*IFERROR(Richard!$U$4:$AA$100,0)),0)+IFERROR(SUMPRODUCT(ISNUMBER(SEARCH(B$2,Jenny!$D$4:$D$100))*IFERROR(Jenny!$U$4:$AA$100,0)),0)+IFERROR(SUMPRODUCT(ISNUMBER(SEARCH(B$2,Cooper!$D$4:$D$100))*IFERROR(Cooper!$U$4:$AA$100,0)),0)+IFERROR(SUMPRODUCT(ISNUMBER(SEARCH(B$2,Summer!$D$4:$D$100))*IFERROR(Summer!$U$4:$AA$100,0)),0)+IFERROR(SUMPRODUCT(ISNUMBER(SEARCH(B$2,Julie!$D$4:$D$100))*IFERROR(Julie!$U$4:$AA$100,0)),0)+IFERROR(SUMPRODUCT(ISNUMBER(SEARCH(B$2,Jiao!$D$4:$D$100))*IFERROR(Jiao!$U$4:$AA$100,0)),0) | C5: ==IFERROR(SUMPRODUCT(ISNUMBER(SEARCH(C$2,KeDa!$D$4:$D$100))*IFERROR(KeDa!$U$4:$AA$100,0)),0)+IFERROR(SUMPRODUCT(ISNUMBER(SEARCH(C$2,Tank!$D$4:$D$100))*IFERROR(Tank!$U$4:$AA$100,0)),0)+IFERROR(SUMPRODUCT(ISNUMBER(SEARCH(C$2,Richard!$D$4:$D$100))*IFERROR(Richard!$U$4:$AA$100,0)),0)+IFERROR(SUMPRODUCT(ISNUMBER(SEARCH(C$2,Jenny!$D$4:$D$100))*IFERROR(Jenny!$U$4:$AA$100,0)),0)+IFERROR(SUMPRODUCT(ISNUMBER(SEARCH(C$2,Cooper!$D$4:$D$100))*IFERROR(Cooper!$U$4:$AA$100,0)),0)+IFERROR(SUMPRODUCT(ISNUMBER(SEARCH(C$2,Summer!$D$4:$D$100))*IFERROR(Summer!$U$4:$AA$100,0)),0)+IFERROR(SUMPRODUCT(ISNUMBER(SEARCH(C$2,Julie!$D$4:$D$100))*IFERROR(Julie!$U$4:$AA$100,0)),0)+IFERROR(SUMPRODUCT(ISNUMBER(SEARCH(C$2,Jiao!$D$4:$D$100))*IFERROR(Jiao!$U$4:$AA$100,0)),0) | D5: ==IFERROR(SUMPRODUCT(ISNUMBER(SEARCH(D$2,KeDa!$D$4:$D$100))*IFERROR(KeDa!$U$4:$AA$100,0)),0)+IFERROR(SUMPRODUCT(ISNUMBER(SEARCH(D$2,Tank!$D$4:$D$100))*IFERROR(Tank!$U$4:$AA$100,0)),0)+IFERROR(SUMPRODUCT(ISNUMBER(SEARCH(D$2,Richard!$D$4:$D$100))*IFERROR(Richard!$U$4:$AA$100,0)),0)+IFERROR(SUMPRODUCT(ISNUMBER(SEARCH(D$2,Jenny!$D$4:$D$100))*IFERROR(Jenny!$U$4:$AA$100,0)),0)+IFERROR(SUMPRODUCT(ISNUMBER(SEARCH(D$2,Cooper!$D$4:$D$100))*IFERROR(Cooper!$U$4:$AA$100,0)),0)+IFERROR(SUMPRODUCT(ISNUMBER(SEARCH(D$2,Summer!$D$4:$D$100))*IFERROR(Summer!$U$4:$AA$100,0)),0)+IFERROR(SUMPRODUCT(ISNUMBER(SEARCH(D$2,Julie!$D$4:$D$100))*IFERROR(Julie!$U$4:$AA$100,0)),0)+IFERROR(SUMPRODUCT(ISNUMBER(SEARCH(D$2,Jiao!$D$4:$D$100))*IFERROR(Jiao!$U$4:$AA$100,0)),0) | E5: ==IFERROR(SUMPRODUCT(ISNUMBER(SEARCH(E$2,KeDa!$D$4:$D$100))*IFERROR(KeDa!$U$4:$AA$100,0)),0)+IFERROR(SUMPRODUCT(ISNUMBER(SEARCH(E$2,Tank!$D$4:$D$100))*IFERROR(Tank!$U$4:$AA$100,0)),0)+IFERROR(SUMPRODUCT(ISNUMBER(SEARCH(E$2,Richard!$D$4:$D$100))*IFERROR(Richard!$U$4:$AA$100,0)),0)+IFERROR(SUMPRODUCT(ISNUMBER(SEARCH(E$2,Jenny!$D$4:$D$100))*IFERROR(Jenny!$U$4:$AA$100,0)),0)+IFERROR(SUMPRODUCT(ISNUMBER(SEARCH(E$2,Cooper!$D$4:$D$100))*IFERROR(Cooper!$U$4:$AA$100,0)),0)+IFERROR(SUMPRODUCT(ISNUMBER(SEARCH(E$2,Summer!$D$4:$D$100))*IFERROR(Summer!$U$4:$AA$100,0)),0)+IFERROR(SUMPRODUCT(ISNUMBER(SEARCH(E$2,Julie!$D$4:$D$100))*IFERROR(Julie!$U$4:$AA$100,0)),0)+IFERROR(SUMPRODUCT(ISNUMBER(SEARCH(E$2,Jiao!$D$4:$D$100))*IFERROR(Jiao!$U$4:$AA$100,0)),0)
A6: 4 | B6: ==IFERROR(SUMPRODUCT(ISNUMBER(SEARCH(B$2,KeDa!$D$4:$D$100))*IFERROR(KeDa!$AC$4:$AI$100,0)),0)+IFERROR(SUMPRODUCT(ISNUMBER(SEARCH(B$2,Tank!$D$4:$D$100))*IFERROR(Tank!$AC$4:$AI$100,0)),0)+IFERROR(SUMPRODUCT(ISNUMBER(SEARCH(B$2,Richard!$D$4:$D$100))*IFERROR(Richard!$AC$4:$AI$100,0)),0)+IFERROR(SUMPRODUCT(ISNUMBER(SEARCH(B$2,Jenny!$D$4:$D$100))*IFERROR(Jenny!$AC$4:$AI$100,0)),0)+IFERROR(SUMPRODUCT(ISNUMBER(SEARCH(B$2,Cooper!$D$4:$D$100))*IFERROR(Cooper!$AC$4:$AI$100,0)),0)+IFERROR(SUMPRODUCT(ISNUMBER(SEARCH(B$2,Summer!$D$4:$D$100))*IFERROR(Summer!$AC$4:$AI$100,0)),0)+IFERROR(SUMPRODUCT(ISNUMBER(SEARCH(B$2,Julie!$D$4:$D$100))*IFERROR(Julie!$AC$4:$AI$100,0)),0)+IFERROR(SUMPRODUCT(ISNUMBER(SEARCH(B$2,Jiao!$D$4:$D$100))*IFERROR(Jiao!$AC$4:$AI$100,0)),0) | C6: ==IFERROR(SUMPRODUCT(ISNUMBER(SEARCH(C$2,KeDa!$D$4:$D$100))*IFERROR(KeDa!$AC$4:$AI$100,0)),0)+IFERROR(SUMPRODUCT(ISNUMBER(SEARCH(C$2,Tank!$D$4:$D$100))*IFERROR(Tank!$AC$4:$AI$100,0)),0)+IFERROR(SUMPRODUCT(ISNUMBER(SEARCH(C$2,Richard!$D$4:$D$100))*IFERROR(Richard!$AC$4:$AI$100,0)),0)+IFERROR(SUMPRODUCT(ISNUMBER(SEARCH(C$2,Jenny!$D$4:$D$100))*IFERROR(Jenny!$AC$4:$AI$100,0)),0)+IFERROR(SUMPRODUCT(ISNUMBER(SEARCH(C$2,Cooper!$D$4:$D$100))*IFERROR(Cooper!$AC$4:$AI$100,0)),0)+IFERROR(SUMPRODUCT(ISNUMBER(SEARCH(C$2,Summer!$D$4:$D$100))*IFERROR(Summer!$AC$4:$AI$100,0)),0)+IFERROR(SUMPRODUCT(ISNUMBER(SEARCH(C$2,Julie!$D$4:$D$100))*IFERROR(Julie!$AC$4:$AI$100,0)),0)+IFERROR(SUMPRODUCT(ISNUMBER(SEARCH(C$2,Jiao!$D$4:$D$100))*IFERROR(Jiao!$AC$4:$AI$100,0)),0) | D6: ==IFERROR(SUMPRODUCT(ISNUMBER(SEARCH(D$2,KeDa!$D$4:$D$100))*IFERROR(KeDa!$AC$4:$AI$100,0)),0)+IFERROR(SUMPRODUCT(ISNUMBER(SEARCH(D$2,Tank!$D$4:$D$100))*IFERROR(Tank!$AC$4:$AI$100,0)),0)+IFERROR(SUMPRODUCT(ISNUMBER(SEARCH(D$2,Richard!$D$4:$D$100))*IFERROR(Richard!$AC$4:$AI$100,0)),0)+IFERROR(SUMPRODUCT(ISNUMBER(SEARCH(D$2,Jenny!$D$4:$D$100))*IFERROR(Jenny!$AC$4:$AI$100,0)),0)+IFERROR(SUMPRODUCT(ISNUMBER(SEARCH(D$2,Cooper!$D$4:$D$100))*IFERROR(Cooper!$AC$4:$AI$100,0)),0)+IFERROR(SUMPRODUCT(ISNUMBER(SEARCH(D$2,Summer!$D$4:$D$100))*IFERROR(Summer!$AC$4:$AI$100,0)),0)+IFERROR(SUMPRODUCT(ISNUMBER(SEARCH(D$2,Julie!$D$4:$D$100))*IFERROR(Julie!$AC$4:$AI$100,0)),0)+IFERROR(SUMPRODUCT(ISNUMBER(SEARCH(D$2,Jiao!$D$4:$D$100))*IFERROR(Jiao!$AC$4:$AI$100,0)),0) | E6: ==IFERROR(SUMPRODUCT(ISNUMBER(SEARCH(E$2,KeDa!$D$4:$D$100))*IFERROR(KeDa!$AC$4:$AI$100,0)),0)+IFERROR(SUMPRODUCT(ISNUMBER(SEARCH(E$2,Tank!$D$4:$D$100))*IFERROR(Tank!$AC$4:$AI$100,0)),0)+IFERROR(SUMPRODUCT(ISNUMBER(SEARCH(E$2,Richard!$D$4:$D$100))*IFERROR(Richard!$AC$4:$AI$100,0)),0)+IFERROR(SUMPRODUCT(ISNUMBER(SEARCH(E$2,Jenny!$D$4:$D$100))*IFERROR(Jenny!$AC$4:$AI$100,0)),0)+IFERROR(SUMPRODUCT(ISNUMBER(SEARCH(E$2,Cooper!$D$4:$D$100))*IFERROR(Cooper!$AC$4:$AI$100,0)),0)+IFERROR(SUMPRODUCT(ISNUMBER(SEARCH(E$2,Summer!$D$4:$D$100))*IFERROR(Summer!$AC$4:$AI$100,0)),0)+IFERROR(SUMPRODUCT(ISNUMBER(SEARCH(E$2,Julie!$D$4:$D$100))*IFERROR(Julie!$AC$4:$AI$100,0)),0)+IFERROR(SUMPRODUCT(ISNUMBER(SEARCH(E$2,Jiao!$D$4:$D$100))*IFERROR(Jiao!$AC$4:$AI$100,0)),0)
A7: 5 | B7: ==IFERROR(SUMPRODUCT(ISNUMBER(SEARCH(B$2,KeDa!$D$4:$D$100))*IFERROR(KeDa!$AK$4:$AQ$100,0)),0)+IFERROR(SUMPRODUCT(ISNUMBER(SEARCH(B$2,Tank!$D$4:$D$100))*IFERROR(Tank!$AK$4:$AQ$100,0)),0)+IFERROR(SUMPRODUCT(ISNUMBER(SEARCH(B$2,Richard!$D$4:$D$100))*IFERROR(Richard!$AK$4:$AQ$100,0)),0)+IFERROR(SUMPRODUCT(ISNUMBER(SEARCH(B$2,Jenny!$D$4:$D$100))*IFERROR(Jenny!$AK$4:$AQ$100,0)),0)+IFERROR(SUMPRODUCT(ISNUMBER(SEARCH(B$2,Cooper!$D$4:$D$100))*IFERROR(Cooper!$AK$4:$AQ$100,0)),0)+IFERROR(SUMPRODUCT(ISNUMBER(SEARCH(B$2,Summer!$D$4:$D$100))*IFERROR(Summer!$AK$4:$AQ$100,0)),0)+IFERROR(SUMPRODUCT(ISNUMBER(SEARCH(B$2,Julie!$D$4:$D$100))*IFERROR(Julie!$AK$4:$AQ$100,0)),0)+IFERROR(SUMPRODUCT(ISNUMBER(SEARCH(B$2,Jiao!$D$4:$D$100))*IFERROR(Jiao!$AK$4:$AQ$100,0)),0) | C7: ==IFERROR(SUMPRODUCT(ISNUMBER(SEARCH(C$2,KeDa!$D$4:$D$100))*IFERROR(KeDa!$AK$4:$AQ$100,0)),0)+IFERROR(SUMPRODUCT(ISNUMBER(SEARCH(C$2,Tank!$D$4:$D$100))*IFERROR(Tank!$AK$4:$AQ$100,0)),0)+IFERROR(SUMPRODUCT(ISNUMBER(SEARCH(C$2,Richard!$D$4:$D$100))*IFERROR(Richard!$AK$4:$AQ$100,0)),0)+IFERROR(SUMPRODUCT(ISNUMBER(SEARCH(C$2,Jenny!$D$4:$D$100))*IFERROR(Jenny!$AK$4:$AQ$100,0)),0)+IFERROR(SUMPRODUCT(ISNUMBER(SEARCH(C$2,Cooper!$D$4:$D$100))*IFERROR(Cooper!$AK$4:$AQ$100,0)),0)+IFERROR(SUMPRODUCT(ISNUMBER(SEARCH(C$2,Summer!$D$4:$D$100))*IFERROR(Summer!$AK$4:$AQ$100,0)),0)+IFERROR(SUMPRODUCT(ISNUMBER(SEARCH(C$2,Julie!$D$4:$D$100))*IFERROR(Julie!$AK$4:$AQ$100,0)),0)+IFERROR(SUMPRODUCT(ISNUMBER(SEARCH(C$2,Jiao!$D$4:$D$100))*IFERROR(Jiao!$AK$4:$AQ$100,0)),0) | D7: ==IFERROR(SUMPRODUCT(ISNUMBER(SEARCH(D$2,KeDa!$D$4:$D$100))*IFERROR(KeDa!$AK$4:$AQ$100,0)),0)+IFERROR(SUMPRODUCT(ISNUMBER(SEARCH(D$2,Tank!$D$4:$D$100))*IFERROR(Tank!$AK$4:$AQ$100,0)),0)+IFERROR(SUMPRODUCT(ISNUMBER(SEARCH(D$2,Richard!$D$4:$D$100))*IFERROR(Richard!$AK$4:$AQ$100,0)),0)+IFERROR(SUMPRODUCT(ISNUMBER(SEARCH(D$2,Jenny!$D$4:$D$100))*IFERROR(Jenny!$AK$4:$AQ$100,0)),0)+IFERROR(SUMPRODUCT(ISNUMBER(SEARCH(D$2,Cooper!$D$4:$D$100))*IFERROR(Cooper!$AK$4:$AQ$100,0)),0)+IFERROR(SUMPRODUCT(ISNUMBER(SEARCH(D$2,Summer!$D$4:$D$100))*IFERROR(Summer!$AK$4:$AQ$100,0)),0)+IFERROR(SUMPRODUCT(ISNUMBER(SEARCH(D$2,Julie!$D$4:$D$100))*IFERROR(Julie!$AK$4:$AQ$100,0)),0)+IFERROR(SUMPRODUCT(ISNUMBER(SEARCH(D$2,Jiao!$D$4:$D$100))*IFERROR(Jiao!$AK$4:$AQ$100,0)),0) | E7: ==IFERROR(SUMPRODUCT(ISNUMBER(SEARCH(E$2,KeDa!$D$4:$D$100))*IFERROR(KeDa!$AK$4:$AQ$100,0)),0)+IFERROR(SUMPRODUCT(ISNUMBER(SEARCH(E$2,Tank!$D$4:$D$100))*IFERROR(Tank!$AK$4:$AQ$100,0)),0)+IFERROR(SUMPRODUCT(ISNUMBER(SEARCH(E$2,Richard!$D$4:$D$100))*IFERROR(Richard!$AK$4:$AQ$100,0)),0)+IFERROR(SUMPRODUCT(ISNUMBER(SEARCH(E$2,Jenny!$D$4:$D$100))*IFERROR(Jenny!$AK$4:$AQ$100,0)),0)+IFERROR(SUMPRODUCT(ISNUMBER(SEARCH(E$2,Cooper!$D$4:$D$100))*IFERROR(Cooper!$AK$4:$AQ$100,0)),0)+IFERROR(SUMPRODUCT(ISNUMBER(SEARCH(E$2,Summer!$D$4:$D$100))*IFERROR(Summer!$AK$4:$AQ$100,0)),0)+IFERROR(SUMPRODUCT(ISNUMBER(SEARCH(E$2,Julie!$D$4:$D$100))*IFERROR(Julie!$AK$4:$AQ$100,0)),0)+IFERROR(SUMPRODUCT(ISNUMBER(SEARCH(E$2,Jiao!$D$4:$D$100))*IFERROR(Jiao!$AK$4:$AQ$100,0)),0)
A8: 6 | B8: ==IFERROR(SUMPRODUCT(ISNUMBER(SEARCH(B$2,KeDa!$D$4:$D$100))*IFERROR(KeDa!$AS$4:$AY$100,0)),0)+IFERROR(SUMPRODUCT(ISNUMBER(SEARCH(B$2,Tank!$D$4:$D$100))*IFERROR(Tank!$AS$4:$AY$100,0)),0)+IFERROR(SUMPRODUCT(ISNUMBER(SEARCH(B$2,Richard!$D$4:$D$100))*IFERROR(Richard!$AS$4:$AY$100,0)),0)+IFERROR(SUMPRODUCT(ISNUMBER(SEARCH(B$2,Jenny!$D$4:$D$100))*IFERROR(Jenny!$AS$4:$AY$100,0)),0)+IFERROR(SUMPRODUCT(ISNUMBER(SEARCH(B$2,Cooper!$D$4:$D$100))*IFERROR(Cooper!$AS$4:$AY$100,0)),0)+IFERROR(SUMPRODUCT(ISNUMBER(SEARCH(B$2,Summer!$D$4:$D$100))*IFERROR(Summer!$AS$4:$AY$100,0)),0)+IFERROR(SUMPRODUCT(ISNUMBER(SEARCH(B$2,Julie!$D$4:$D$100))*IFERROR(Julie!$AS$4:$AY$100,0)),0)+IFERROR(SUMPRODUCT(ISNUMBER(SEARCH(B$2,Jiao!$D$4:$D$100))*IFERROR(Jiao!$AS$4:$AY$100,0)),0) | C8: ==IFERROR(SUMPRODUCT(ISNUMBER(SEARCH(C$2,KeDa!$D$4:$D$100))*IFERROR(KeDa!$AS$4:$AY$100,0)),0)+IFERROR(SUMPRODUCT(ISNUMBER(SEARCH(C$2,Tank!$D$4:$D$100))*IFERROR(Tank!$AS$4:$AY$100,0)),0)+IFERROR(SUMPRODUCT(ISNUMBER(SEARCH(C$2,Richard!$D$4:$D$100))*IFERROR(Richard!$AS$4:$AY$100,0)),0)+IFERROR(SUMPRODUCT(ISNUMBER(SEARCH(C$2,Jenny!$D$4:$D$100))*IFERROR(Jenny!$AS$4:$AY$100,0)),0)+IFERROR(SUMPRODUCT(ISNUMBER(SEARCH(C$2,Cooper!$D$4:$D$100))*IFERROR(Cooper!$AS$4:$AY$100,0)),0)+IFERROR(SUMPRODUCT(ISNUMBER(SEARCH(C$2,Summer!$D$4:$D$100))*IFERROR(Summer!$AS$4:$AY$100,0)),0)+IFERROR(SUMPRODUCT(ISNUMBER(SEARCH(C$2,Julie!$D$4:$D$100))*IFERROR(Julie!$AS$4:$AY$100,0)),0)+IFERROR(SUMPRODUCT(ISNUMBER(SEARCH(C$2,Jiao!$D$4:$D$100))*IFERROR(Jiao!$AS$4:$AY$100,0)),0) | D8: ==IFERROR(SUMPRODUCT(ISNUMBER(SEARCH(D$2,KeDa!$D$4:$D$100))*IFERROR(KeDa!$AS$4:$AY$100,0)),0)+IFERROR(SUMPRODUCT(ISNUMBER(SEARCH(D$2,Tank!$D$4:$D$100))*IFERROR(Tank!$AS$4:$AY$100,0)),0)+IFERROR(SUMPRODUCT(ISNUMBER(SEARCH(D$2,Richard!$D$4:$D$100))*IFERROR(Richard!$AS$4:$AY$100,0)),0)+IFERROR(SUMPRODUCT(ISNUMBER(SEARCH(D$2,Jenny!$D$4:$D$100))*IFERROR(Jenny!$AS$4:$AY$100,0)),0)+IFERROR(SUMPRODUCT(ISNUMBER(SEARCH(D$2,Cooper!$D$4:$D$100))*IFERROR(Cooper!$AS$4:$AY$100,0)),0)+IFERROR(SUMPRODUCT(ISNUMBER(SEARCH(D$2,Summer!$D$4:$D$100))*IFERROR(Summer!$AS$4:$AY$100,0)),0)+IFERROR(SUMPRODUCT(ISNUMBER(SEARCH(D$2,Julie!$D$4:$D$100))*IFERROR(Julie!$AS$4:$AY$100,0)),0)+IFERROR(SUMPRODUCT(ISNUMBER(SEARCH(D$2,Jiao!$D$4:$D$100))*IFERROR(Jiao!$AS$4:$AY$100,0)),0) | E8: ==IFERROR(SUMPRODUCT(ISNUMBER(SEARCH(E$2,KeDa!$D$4:$D$100))*IFERROR(KeDa!$AS$4:$AY$100,0)),0)+IFERROR(SUMPRODUCT(ISNUMBER(SEARCH(E$2,Tank!$D$4:$D$100))*IFERROR(Tank!$AS$4:$AY$100,0)),0)+IFERROR(SUMPRODUCT(ISNUMBER(SEARCH(E$2,Richard!$D$4:$D$100))*IFERROR(Richard!$AS$4:$AY$100,0)),0)+IFERROR(SUMPRODUCT(ISNUMBER(SEARCH(E$2,Jenny!$D$4:$D$100))*IFERROR(Jenny!$AS$4:$AY$100,0)),0)+IFERROR(SUMPRODUCT(ISNUMBER(SEARCH(E$2,Cooper!$D$4:$D$100))*IFERROR(Cooper!$AS$4:$AY$100,0)),0)+IFERROR(SUMPRODUCT(ISNUMBER(SEARCH(E$2,Summer!$D$4:$D$100))*IFERROR(Summer!$AS$4:$AY$100,0)),0)+IFERROR(SUMPRODUCT(ISNUMBER(SEARCH(E$2,Julie!$D$4:$D$100))*IFERROR(Julie!$AS$4:$AY$100,0)),0)+IFERROR(SUMPRODUCT(ISNUMBER(SEARCH(E$2,Jiao!$D$4:$D$100))*IFERROR(Jiao!$AS$4:$AY$100,0)),0)
A9: 7 | B9: ==IFERROR(SUMPRODUCT(ISNUMBER(SEARCH(B$2,KeDa!$D$4:$D$100))*IFERROR(KeDa!$BA$4:$BG$100,0)),0)+IFERROR(SUMPRODUCT(ISNUMBER(SEARCH(B$2,Tank!$D$4:$D$100))*IFERROR(Tank!$BA$4:$BG$100,0)),0)+IFERROR(SUMPRODUCT(ISNUMBER(SEARCH(B$2,Richard!$D$4:$D$100))*IFERROR(Richard!$BA$4:$BG$100,0)),0)+IFERROR(SUMPRODUCT(ISNUMBER(SEARCH(B$2,Jenny!$D$4:$D$100))*IFERROR(Jenny!$BA$4:$BG$100,0)),0)+IFERROR(SUMPRODUCT(ISNUMBER(SEARCH(B$2,Cooper!$D$4:$D$100))*IFERROR(Cooper!$BA$4:$BG$100,0)),0)+IFERROR(SUMPRODUCT(ISNUMBER(SEARCH(B$2,Summer!$D$4:$D$100))*IFERROR(Summer!$BA$4:$BG$100,0)),0)+IFERROR(SUMPRODUCT(ISNUMBER(SEARCH(B$2,Julie!$D$4:$D$100))*IFERROR(Julie!$BA$4:$BG$100,0)),0)+IFERROR(SUMPRODUCT(ISNUMBER(SEARCH(B$2,Jiao!$D$4:$D$100))*IFERROR(Jiao!$BA$4:$BG$100,0)),0) | C9: ==IFERROR(SUMPRODUCT(ISNUMBER(SEARCH(C$2,KeDa!$D$4:$D$100))*IFERROR(KeDa!$BA$4:$BG$100,0)),0)+IFERROR(SUMPRODUCT(ISNUMBER(SEARCH(C$2,Tank!$D$4:$D$100))*IFERROR(Tank!$BA$4:$BG$100,0)),0)+IFERROR(SUMPRODUCT(ISNUMBER(SEARCH(C$2,Richard!$D$4:$D$100))*IFERROR(Richard!$BA$4:$BG$100,0)),0)+IFERROR(SUMPRODUCT(ISNUMBER(SEARCH(C$2,Jenny!$D$4:$D$100))*IFERROR(Jenny!$BA$4:$BG$100,0)),0)+IFERROR(SUMPRODUCT(ISNUMBER(SEARCH(C$2,Cooper!$D$4:$D$100))*IFERROR(Cooper!$BA$4:$BG$100,0)),0)+IFERROR(SUMPRODUCT(ISNUMBER(SEARCH(C$2,Summer!$D$4:$D$100))*IFERROR(Summer!$BA$4:$BG$100,0)),0)+IFERROR(SUMPRODUCT(ISNUMBER(SEARCH(C$2,Julie!$D$4:$D$100))*IFERROR(Julie!$BA$4:$BG$100,0)),0)+IFERROR(SUMPRODUCT(ISNUMBER(SEARCH(C$2,Jiao!$D$4:$D$100))*IFERROR(Jiao!$BA$4:$BG$100,0)),0) | D9: ==IFERROR(SUMPRODUCT(ISNUMBER(SEARCH(D$2,KeDa!$D$4:$D$100))*IFERROR(KeDa!$BA$4:$BG$100,0)),0)+IFERROR(SUMPRODUCT(ISNUMBER(SEARCH(D$2,Tank!$D$4:$D$100))*IFERROR(Tank!$BA$4:$BG$100,0)),0)+IFERROR(SUMPRODUCT(ISNUMBER(SEARCH(D$2,Richard!$D$4:$D$100))*IFERROR(Richard!$BA$4:$BG$100,0)),0)+IFERROR(SUMPRODUCT(ISNUMBER(SEARCH(D$2,Jenny!$D$4:$D$100))*IFERROR(Jenny!$BA$4:$BG$100,0)),0)+IFERROR(SUMPRODUCT(ISNUMBER(SEARCH(D$2,Cooper!$D$4:$D$100))*IFERROR(Cooper!$BA$4:$BG$100,0)),0)+IFERROR(SUMPRODUCT(ISNUMBER(SEARCH(D$2,Summer!$D$4:$D$100))*IFERROR(Summer!$BA$4:$BG$100,0)),0)+IFERROR(SUMPRODUCT(ISNUMBER(SEARCH(D$2,Julie!$D$4:$D$100))*IFERROR(Julie!$BA$4:$BG$100,0)),0)+IFERROR(SUMPRODUCT(ISNUMBER(SEARCH(D$2,Jiao!$D$4:$D$100))*IFERROR(Jiao!$BA$4:$BG$100,0)),0) | E9: ==IFERROR(SUMPRODUCT(ISNUMBER(SEARCH(E$2,KeDa!$D$4:$D$100))*IFERROR(KeDa!$BA$4:$BG$100,0)),0)+IFERROR(SUMPRODUCT(ISNUMBER(SEARCH(E$2,Tank!$D$4:$D$100))*IFERROR(Tank!$BA$4:$BG$100,0)),0)+IFERROR(SUMPRODUCT(ISNUMBER(SEARCH(E$2,Richard!$D$4:$D$100))*IFERROR(Richard!$BA$4:$BG$100,0)),0)+IFERROR(SUMPRODUCT(ISNUMBER(SEARCH(E$2,Jenny!$D$4:$D$100))*IFERROR(Jenny!$BA$4:$BG$100,0)),0)+IFERROR(SUMPRODUCT(ISNUMBER(SEARCH(E$2,Cooper!$D$4:$D$100))*IFERROR(Cooper!$BA$4:$BG$100,0)),0)+IFERROR(SUMPRODUCT(ISNUMBER(SEARCH(E$2,Summer!$D$4:$D$100))*IFERROR(Summer!$BA$4:$BG$100,0)),0)+IFERROR(SUMPRODUCT(ISNUMBER(SEARCH(E$2,Julie!$D$4:$D$100))*IFERROR(Julie!$BA$4:$BG$100,0)),0)+IFERROR(SUMPRODUCT(ISNUMBER(SEARCH(E$2,Jiao!$D$4:$D$100))*IFERROR(Jiao!$BA$4:$BG$100,0)),0)
A10: 8 | B10: ==IFERROR(SUMPRODUCT(ISNUMBER(SEARCH(B$2,KeDa!$D$4:$D$100))*IFERROR(KeDa!$BI$4:$BO$100,0)),0)+IFERROR(SUMPRODUCT(ISNUMBER(SEARCH(B$2,Tank!$D$4:$D$100))*IFERROR(Tank!$BI$4:$BO$100,0)),0)+IFERROR(SUMPRODUCT(ISNUMBER(SEARCH(B$2,Richard!$D$4:$D$100))*IFERROR(Richard!$BI$4:$BO$100,0)),0)+IFERROR(SUMPRODUCT(ISNUMBER(SEARCH(B$2,Jenny!$D$4:$D$100))*IFERROR(Jenny!$BI$4:$BO$100,0)),0)+IFERROR(SUMPRODUCT(ISNUMBER(SEARCH(B$2,Cooper!$D$4:$D$100))*IFERROR(Cooper!$BI$4:$BO$100,0)),0)+IFERROR(SUMPRODUCT(ISNUMBER(SEARCH(B$2,Summer!$D$4:$D$100))*IFERROR(Summer!$BI$4:$BO$100,0)),0)+IFERROR(SUMPRODUCT(ISNUMBER(SEARCH(B$2,Julie!$D$4:$D$100))*IFERROR(Julie!$BI$4:$BO$100,0)),0)+IFERROR(SUMPRODUCT(ISNUMBER(SEARCH(B$2,Jiao!$D$4:$D$100))*IFERROR(Jiao!$BI$4:$BO$100,0)),0) | C10: ==IFERROR(SUMPRODUCT(ISNUMBER(SEARCH(C$2,KeDa!$D$4:$D$100))*IFERROR(KeDa!$BI$4:$BO$100,0)),0)+IFERROR(SUMPRODUCT(ISNUMBER(SEARCH(C$2,Tank!$D$4:$D$100))*IFERROR(Tank!$BI$4:$BO$100,0)),0)+IFERROR(SUMPRODUCT(ISNUMBER(SEARCH(C$2,Richard!$D$4:$D$100))*IFERROR(Richard!$BI$4:$BO$100,0)),0)+IFERROR(SUMPRODUCT(ISNUMBER(SEARCH(C$2,Jenny!$D$4:$D$100))*IFERROR(Jenny!$BI$4:$BO$100,0)),0)+IFERROR(SUMPRODUCT(ISNUMBER(SEARCH(C$2,Cooper!$D$4:$D$100))*IFERROR(Cooper!$BI$4:$BO$100,0)),0)+IFERROR(SUMPRODUCT(ISNUMBER(SEARCH(C$2,Summer!$D$4:$D$100))*IFERROR(Summer!$BI$4:$BO$100,0)),0)+IFERROR(SUMPRODUCT(ISNUMBER(SEARCH(C$2,Julie!$D$4:$D$100))*IFERROR(Julie!$BI$4:$BO$100,0)),0)+IFERROR(SUMPRODUCT(ISNUMBER(SEARCH(C$2,Jiao!$D$4:$D$100))*IFERROR(Jiao!$BI$4:$BO$100,0)),0) | D10: ==IFERROR(SUMPRODUCT(ISNUMBER(SEARCH(D$2,KeDa!$D$4:$D$100))*IFERROR(KeDa!$BI$4:$BO$100,0)),0)+IFERROR(SUMPRODUCT(ISNUMBER(SEARCH(D$2,Tank!$D$4:$D$100))*IFERROR(Tank!$BI$4:$BO$100,0)),0)+IFERROR(SUMPRODUCT(ISNUMBER(SEARCH(D$2,Richard!$D$4:$D$100))*IFERROR(Richard!$BI$4:$BO$100,0)),0)+IFERROR(SUMPRODUCT(ISNUMBER(SEARCH(D$2,Jenny!$D$4:$D$100))*IFERROR(Jenny!$BI$4:$BO$100,0)),0)+IFERROR(SUMPRODUCT(ISNUMBER(SEARCH(D$2,Cooper!$D$4:$D$100))*IFERROR(Cooper!$BI$4:$BO$100,0)),0)+IFERROR(SUMPRODUCT(ISNUMBER(SEARCH(D$2,Summer!$D$4:$D$100))*IFERROR(Summer!$BI$4:$BO$100,0)),0)+IFERROR(SUMPRODUCT(ISNUMBER(SEARCH(D$2,Julie!$D$4:$D$100))*IFERROR(Julie!$BI$4:$BO$100,0)),0)+IFERROR(SUMPRODUCT(ISNUMBER(SEARCH(D$2,Jiao!$D$4:$D$100))*IFERROR(Jiao!$BI$4:$BO$100,0)),0) | E10: ==IFERROR(SUMPRODUCT(ISNUMBER(SEARCH(E$2,KeDa!$D$4:$D$100))*IFERROR(KeDa!$BI$4:$BO$100,0)),0)+IFERROR(SUMPRODUCT(ISNUMBER(SEARCH(E$2,Tank!$D$4:$D$100))*IFERROR(Tank!$BI$4:$BO$100,0)),0)+IFERROR(SUMPRODUCT(ISNUMBER(SEARCH(E$2,Richard!$D$4:$D$100))*IFERROR(Richard!$BI$4:$BO$100,0)),0)+IFERROR(SUMPRODUCT(ISNUMBER(SEARCH(E$2,Jenny!$D$4:$D$100))*IFERROR(Jenny!$BI$4:$BO$100,0)),0)+IFERROR(SUMPRODUCT(ISNUMBER(SEARCH(E$2,Cooper!$D$4:$D$100))*IFERROR(Cooper!$BI$4:$BO$100,0)),0)+IFERROR(SUMPRODUCT(ISNUMBER(SEARCH(E$2,Summer!$D$4:$D$100))*IFERROR(Summer!$BI$4:$BO$100,0)),0)+IFERROR(SUMPRODUCT(ISNUMBER(SEARCH(E$2,Julie!$D$4:$D$100))*IFERROR(Julie!$BI$4:$BO$100,0)),0)+IFERROR(SUMPRODUCT(ISNUMBER(SEARCH(E$2,Jiao!$D$4:$D$100))*IFERROR(Jiao!$BI$4:$BO$100,0)),0)
A11: 9 | B11: ==IFERROR(SUMPRODUCT(ISNUMBER(SEARCH(B$2,KeDa!$D$4:$D$100))*IFERROR(KeDa!$BQ$4:$BW$100,0)),0)+IFERROR(SUMPRODUCT(ISNUMBER(SEARCH(B$2,Tank!$D$4:$D$100))*IFERROR(Tank!$BQ$4:$BW$100,0)),0)+IFERROR(SUMPRODUCT(ISNUMBER(SEARCH(B$2,Richard!$D$4:$D$100))*IFERROR(Richard!$BQ$4:$BW$100,0)),0)+IFERROR(SUMPRODUCT(ISNUMBER(SEARCH(B$2,Jenny!$D$4:$D$100))*IFERROR(Jenny!$BQ$4:$BW$100,0)),0)+IFERROR(SUMPRODUCT(ISNUMBER(SEARCH(B$2,Cooper!$D$4:$D$100))*IFERROR(Cooper!$BQ$4:$BW$100,0)),0)+IFERROR(SUMPRODUCT(ISNUMBER(SEARCH(B$2,Summer!$D$4:$D$100))*IFERROR(Summer!$BQ$4:$BW$100,0)),0)+IFERROR(SUMPRODUCT(ISNUMBER(SEARCH(B$2,Julie!$D$4:$D$100))*IFERROR(Julie!$BQ$4:$BW$100,0)),0)+IFERROR(SUMPRODUCT(ISNUMBER(SEARCH(B$2,Jiao!$D$4:$D$100))*IFERROR(Jiao!$BQ$4:$BW$100,0)),0) | C11: ==IFERROR(SUMPRODUCT(ISNUMBER(SEARCH(C$2,KeDa!$D$4:$D$100))*IFERROR(KeDa!$BQ$4:$BW$100,0)),0)+IFERROR(SUMPRODUCT(ISNUMBER(SEARCH(C$2,Tank!$D$4:$D$100))*IFERROR(Tank!$BQ$4:$BW$100,0)),0)+IFERROR(SUMPRODUCT(ISNUMBER(SEARCH(C$2,Richard!$D$4:$D$100))*IFERROR(Richard!$BQ$4:$BW$100,0)),0)+IFERROR(SUMPRODUCT(ISNUMBER(SEARCH(C$2,Jenny!$D$4:$D$100))*IFERROR(Jenny!$BQ$4:$BW$100,0)),0)+IFERROR(SUMPRODUCT(ISNUMBER(SEARCH(C$2,Cooper!$D$4:$D$100))*IFERROR(Cooper!$BQ$4:$BW$100,0)),0)+IFERROR(SUMPRODUCT(ISNUMBER(SEARCH(C$2,Summer!$D$4:$D$100))*IFERROR(Summer!$BQ$4:$BW$100,0)),0)+IFERROR(SUMPRODUCT(ISNUMBER(SEARCH(C$2,Julie!$D$4:$D$100))*IFERROR(Julie!$BQ$4:$BW$100,0)),0)+IFERROR(SUMPRODUCT(ISNUMBER(SEARCH(C$2,Jiao!$D$4:$D$100))*IFERROR(Jiao!$BQ$4:$BW$100,0)),0) | D11: ==IFERROR(SUMPRODUCT(ISNUMBER(SEARCH(D$2,KeDa!$D$4:$D$100))*IFERROR(KeDa!$BQ$4:$BW$100,0)),0)+IFERROR(SUMPRODUCT(ISNUMBER(SEARCH(D$2,Tank!$D$4:$D$100))*IFERROR(Tank!$BQ$4:$BW$100,0)),0)+IFERROR(SUMPRODUCT(ISNUMBER(SEARCH(D$2,Richard!$D$4:$D$100))*IFERROR(Richard!$BQ$4:$BW$100,0)),0)+IFERROR(SUMPRODUCT(ISNUMBER(SEARCH(D$2,Jenny!$D$4:$D$100))*IFERROR(Jenny!$BQ$4:$BW$100,0)),0)+IFERROR(SUMPRODUCT(ISNUMBER(SEARCH(D$2,Cooper!$D$4:$D$100))*IFERROR(Cooper!$BQ$4:$BW$100,0)),0)+IFERROR(SUMPRODUCT(ISNUMBER(SEARCH(D$2,Summer!$D$4:$D$100))*IFERROR(Summer!$BQ$4:$BW$100,0)),0)+IFERROR(SUMPRODUCT(ISNUMBER(SEARCH(D$2,Julie!$D$4:$D$100))*IFERROR(Julie!$BQ$4:$BW$100,0)),0)+IFERROR(SUMPRODUCT(ISNUMBER(SEARCH(D$2,Jiao!$D$4:$D$100))*IFERROR(Jiao!$BQ$4:$BW$100,0)),0) | E11: ==IFERROR(SUMPRODUCT(ISNUMBER(SEARCH(E$2,KeDa!$D$4:$D$100))*IFERROR(KeDa!$BQ$4:$BW$100,0)),0)+IFERROR(SUMPRODUCT(ISNUMBER(SEARCH(E$2,Tank!$D$4:$D$100))*IFERROR(Tank!$BQ$4:$BW$100,0)),0)+IFERROR(SUMPRODUCT(ISNUMBER(SEARCH(E$2,Richard!$D$4:$D$100))*IFERROR(Richard!$BQ$4:$BW$100,0)),0)+IFERROR(SUMPRODUCT(ISNUMBER(SEARCH(E$2,Jenny!$D$4:$D$100))*IFERROR(Jenny!$BQ$4:$BW$100,0)),0)+IFERROR(SUMPRODUCT(ISNUMBER(SEARCH(E$2,Cooper!$D$4:$D$100))*IFERROR(Cooper!$BQ$4:$BW$100,0)),0)+IFERROR(SUMPRODUCT(ISNUMBER(SEARCH(E$2,Summer!$D$4:$D$100))*IFERROR(Summer!$BQ$4:$BW$100,0)),0)+IFERROR(SUMPRODUCT(ISNUMBER(SEARCH(E$2,Julie!$D$4:$D$100))*IFERROR(Julie!$BQ$4:$BW$100,0)),0)+IFERROR(SUMPRODUCT(ISNUMBER(SEARCH(E$2,Jiao!$D$4:$D$100))*IFERROR(Jiao!$BQ$4:$BW$100,0)),0)
A12: 10 | B12: ==IFERROR(SUMPRODUCT(ISNUMBER(SEARCH(B$2,KeDa!$D$4:$D$100))*IFERROR(KeDa!$BY$4:$CE$100,0)),0)+IFERROR(SUMPRODUCT(ISNUMBER(SEARCH(B$2,Tank!$D$4:$D$100))*IFERROR(Tank!$BY$4:$CE$100,0)),0)+IFERROR(SUMPRODUCT(ISNUMBER(SEARCH(B$2,Richard!$D$4:$D$100))*IFERROR(Richard!$BY$4:$CE$100,0)),0)+IFERROR(SUMPRODUCT(ISNUMBER(SEARCH(B$2,Jenny!$D$4:$D$100))*IFERROR(Jenny!$BY$4:$CE$100,0)),0)+IFERROR(SUMPRODUCT(ISNUMBER(SEARCH(B$2,Cooper!$D$4:$D$100))*IFERROR(Cooper!$BY$4:$CE$100,0)),0)+IFERROR(SUMPRODUCT(ISNUMBER(SEARCH(B$2,Summer!$D$4:$D$100))*IFERROR(Summer!$BY$4:$CE$100,0)),0)+IFERROR(SUMPRODUCT(ISNUMBER(SEARCH(B$2,Julie!$D$4:$D$100))*IFERROR(Julie!$BY$4:$CE$100,0)),0)+IFERROR(SUMPRODUCT(ISNUMBER(SEARCH(B$2,Jiao!$D$4:$D$100))*IFERROR(Jiao!$BY$4:$CE$100,0)),0) | C12: ==IFERROR(SUMPRODUCT(ISNUMBER(SEARCH(C$2,KeDa!$D$4:$D$100))*IFERROR(KeDa!$BY$4:$CE$100,0)),0)+IFERROR(SUMPRODUCT(ISNUMBER(SEARCH(C$2,Tank!$D$4:$D$100))*IFERROR(Tank!$BY$4:$CE$100,0)),0)+IFERROR(SUMPRODUCT(ISNUMBER(SEARCH(C$2,Richard!$D$4:$D$100))*IFERROR(Richard!$BY$4:$CE$100,0)),0)+IFERROR(SUMPRODUCT(ISNUMBER(SEARCH(C$2,Jenny!$D$4:$D$100))*IFERROR(Jenny!$BY$4:$CE$100,0)),0)+IFERROR(SUMPRODUCT(ISNUMBER(SEARCH(C$2,Cooper!$D$4:$D$100))*IFERROR(Cooper!$BY$4:$CE$100,0)),0)+IFERROR(SUMPRODUCT(ISNUMBER(SEARCH(C$2,Summer!$D$4:$D$100))*IFERROR(Summer!$BY$4:$CE$100,0)),0)+IFERROR(SUMPRODUCT(ISNUMBER(SEARCH(C$2,Julie!$D$4:$D$100))*IFERROR(Julie!$BY$4:$CE$100,0)),0)+IFERROR(SUMPRODUCT(ISNUMBER(SEARCH(C$2,Jiao!$D$4:$D$100))*IFERROR(Jiao!$BY$4:$CE$100,0)),0) | D12: ==IFERROR(SUMPRODUCT(ISNUMBER(SEARCH(D$2,KeDa!$D$4:$D$100))*IFERROR(KeDa!$BY$4:$CE$100,0)),0)+IFERROR(SUMPRODUCT(ISNUMBER(SEARCH(D$2,Tank!$D$4:$D$100))*IFERROR(Tank!$BY$4:$CE$100,0)),0)+IFERROR(SUMPRODUCT(ISNUMBER(SEARCH(D$2,Richard!$D$4:$D$100))*IFERROR(Richard!$BY$4:$CE$100,0)),0)+IFERROR(SUMPRODUCT(ISNUMBER(SEARCH(D$2,Jenny!$D$4:$D$100))*IFERROR(Jenny!$BY$4:$CE$100,0)),0)+IFERROR(SUMPRODUCT(ISNUMBER(SEARCH(D$2,Cooper!$D$4:$D$100))*IFERROR(Cooper!$BY$4:$CE$100,0)),0)+IFERROR(SUMPRODUCT(ISNUMBER(SEARCH(D$2,Summer!$D$4:$D$100))*IFERROR(Summer!$BY$4:$CE$100,0)),0)+IFERROR(SUMPRODUCT(ISNUMBER(SEARCH(D$2,Julie!$D$4:$D$100))*IFERROR(Julie!$BY$4:$CE$100,0)),0)+IFERROR(SUMPRODUCT(ISNUMBER(SEARCH(D$2,Jiao!$D$4:$D$100))*IFERROR(Jiao!$BY$4:$CE$100,0)),0) | E12: ==IFERROR(SUMPRODUCT(ISNUMBER(SEARCH(E$2,KeDa!$D$4:$D$100))*IFERROR(KeDa!$BY$4:$CE$100,0)),0)+IFERROR(SUMPRODUCT(ISNUMBER(SEARCH(E$2,Tank!$D$4:$D$100))*IFERROR(Tank!$BY$4:$CE$100,0)),0)+IFERROR(SUMPRODUCT(ISNUMBER(SEARCH(E$2,Richard!$D$4:$D$100))*IFERROR(Richard!$BY$4:$CE$100,0)),0)+IFERROR(SUMPRODUCT(ISNUMBER(SEARCH(E$2,Jenny!$D$4:$D$100))*IFERROR(Jenny!$BY$4:$CE$100,0)),0)+IFERROR(SUMPRODUCT(ISNUMBER(SEARCH(E$2,Cooper!$D$4:$D$100))*IFERROR(Cooper!$BY$4:$CE$100,0)),0)+IFERROR(SUMPRODUCT(ISNUMBER(SEARCH(E$2,Summer!$D$4:$D$100))*IFERROR(Summer!$BY$4:$CE$100,0)),0)+IFERROR(SUMPRODUCT(ISNUMBER(SEARCH(E$2,Julie!$D$4:$D$100))*IFERROR(Julie!$BY$4:$CE$100,0)),0)+IFERROR(SUMPRODUCT(ISNUMBER(SEARCH(E$2,Jiao!$D$4:$D$100))*IFERROR(Jiao!$BY$4:$CE$100,0)),0)
A13: Total Housepoints | B13: ==SUM(B3:B12) | C13: ==SUM(C3:C12) | D13: ==SUM(D3:D12) | E13: ==SUM(E3:E12)
A14: Point Allocation (Positive Reinforcement – Award Points) Students earn points for their house through: A. Participation & Engagement +5 pts – Active participation in discussions/activities +10 pts – Leading a group task successfully +5 pts – Asking thoughtful questions B. Teamwork & Respect +10 pts – Helping a peer without being asked +15 pts – Resolving a conflict peacefully +5 pts – Encouraging a shy student to participate C. Academic Excellence +10 pts – Outstanding homework/project +15 pts – Creative problem-solving +20 pts – Winning a quiz/competition D. Leadership & Initiative +10 pts – Organizing a team strategy +15 pts – Volunteering for extra responsibilities E. Additional Features to Boost Engagement *Daily Bonus Challenges (e.g., "Best Team Spirit" = +20 pts) | C14: Point Deduction (Negative Reinforcement – Penalties) Students lose points for their house due to: A. Disrespect & Misbehavior -10 pts – Disrupting class/being rude -15 pts – Bullying or exclusion -20 pts – Cheating/lying B. Lack of Effort -5 pts – Not completing homework -10 pts – Refusing to participate -15 pts – Sabotaging team efforts C. Rule Violations -10 pts – Unauthorized phone/device use -15 pts – Leaving camp area without permission
A21: 1 E:K
A22: 2 M:S
A23: 3 U:AA
A24: 4 AC:AI
A25: 5 AK:AQ
A26: 6 AS:AY
A27: 7 BA:BG
A28: 8 BI:BO
A29: 9 BQ:BW
A30: 10 BY:CE

Sheet Tesla
A1: House of Tesla | E1: Point Allocation- Award Points | I1: Point Deduction - Penalties
A2: 序号No. | B2: 姓名 Name | C2: 年级 Grade Level | D2: House | E2: Participation & Engagement | F2: Teamwork & Respect | G2: Academic Excellence | H2: Leadership & Initiative | I2: Disrespect & Misbehavior | J2: Lack of Effort | K2: Rule Violations
A3: 1 | B3: 张哲燃 Ethan | C3: G6 | D3: Tesla | E3: ==IFERROR(SUMPRODUCT((ISNUMBER(SEARCH($B3,KeDa!$B$4:$B$100)))*(LEFT(TRIM(KeDa!$E$3:$CE$3),LEN(TRIM(E$2)))=TRIM(E$2))*IFERROR(KeDa!$E$4:$CE$100,0)),0)+IFERROR(SUMPRODUCT((ISNUMBER(SEARCH($B3,Tank!$B$4:$B$100)))*(LEFT(TRIM(Tank!$E$3:$CE$3),LEN(TRIM(E$2)))=TRIM(E$2))*IFERROR(Tank!$E$4:$CE$100,0)),0)+IFERROR(SUMPRODUCT((ISNUMBER(SEARCH($B3,Richard!$B$4:$B$100)))*(LEFT(TRIM(Richard!$E$3:$CE$3),LEN(TRIM(E$2)))=TRIM(E$2))*IFERROR(Richard!$E$4:$CE$100,0)),0)+IFERROR(SUMPRODUCT((ISNUMBER(SEARCH($B3,Jenny!$B$4:$B$100)))*(LEFT(TRIM(Jenny!$E$3:$CE$3),LEN(TRIM(E$2)))=TRIM(E$2))*IFERROR(Jenny!$E$4:$CE$100,0)),0)+IFERROR(SUMPRODUCT((ISNUMBER(SEARCH($B3,Cooper!$B$4:$B$100)))*(LEFT(TRIM(Cooper!$E$3:$CE$3),LEN(TRIM(E$2)))=TRIM(E$2))*IFERROR(Cooper!$E$4:$CE$100,0)),0)+IFERROR(SUMPRODUCT((ISNUMBER(SEARCH($B3,Summer!$B$4:$B$100)))*(LEFT(TRIM(Summer!$E$3:$CE$3),LEN(TRIM(E$2)))=TRIM(E$2))*IFERROR(Summer!$E$4:$CE$100,0)),0)+IFERROR(SUMPRODUCT((ISNUMBER(SEARCH($B3,Julie!$B$4:$B$100)))*(LEFT(TRIM(Julie!$E$3:$CE$3),LEN(TRIM(E$2)))=TRIM(E$2))*IFERROR(Julie!$E$4:$CE$100,0)),0)+IFERROR(SUMPRODUCT((ISNUMBER(SEARCH($B3,Jiao!$B$4:$B$100)))*(LEFT(TRIM(Jiao!$E$3:$CE$3),LEN(TRIM(E$2)))=TRIM(E$2))*IFERROR(Jiao!$E$4:$CE$100,0)),0) | F3: ==IFERROR(SUMPRODUCT((ISNUMBER(SEARCH($B3,KeDa!$B$4:$B$100)))*(LEFT(TRIM(KeDa!$E$3:$CE$3),LEN(TRIM(F$2)))=TRIM(F$2))*IFERROR(KeDa!$E$4:$CE$100,0)),0)+IFERROR(SUMPRODUCT((ISNUMBER(SEARCH($B3,Tank!$B$4:$B$100)))*(LEFT(TRIM(Tank!$E$3:$CE$3),LEN(TRIM(F$2)))=TRIM(F$2))*IFERROR(Tank!$E$4:$CE$100,0)),0)+IFERROR(SUMPRODUCT((ISNUMBER(SEARCH($B3,Richard!$B$4:$B$100)))*(LEFT(TRIM(Richard!$E$3:$CE$3),LEN(TRIM(F$2)))=TRIM(F$2))*IFERROR(Richard!$E$4:$CE$100,0)),0)+IFERROR(SUMPRODUCT((ISNUMBER(SEARCH($B3,Jenny!$B$4:$B$100)))*(LEFT(TRIM(Jenny!$E$3:$CE$3),LEN(TRIM(F$2)))=TRIM(F$2))*IFERROR(Jenny!$E$4:$CE$100,0)),0)+IFERROR(SUMPRODUCT((ISNUMBER(SEARCH($B3,Cooper!$B$4:$B$100)))*(LEFT(TRIM(Cooper!$E$3:$CE$3),LEN(TRIM(F$2)))=TRIM(F$2))*IFERROR(Cooper!$E$4:$CE$100,0)),0)+IFERROR(SUMPRODUCT((ISNUMBER(SEARCH($B3,Summer!$B$4:$B$100)))*(LEFT(TRIM(Summer!$E$3:$CE$3),LEN(TRIM(F$2)))=TRIM(F$2))*IFERROR(Summer!$E$4:$CE$100,0)),0)+IFERROR(SUMPRODUCT((ISNUMBER(SEARCH($B3,Julie!$B$4:$B$100)))*(LEFT(TRIM(Julie!$E$3:$CE$3),LEN(TRIM(F$2)))=TRIM(F$2))*IFERROR(Julie!$E$4:$CE$100,0)),0)+IFERROR(SUMPRODUCT((ISNUMBER(SEARCH($B3,Jiao!$B$4:$B$100)))*(LEFT(TRIM(Jiao!$E$3:$CE$3),LEN(TRIM(F$2)))=TRIM(F$2))*IFERROR(Jiao!$E$4:$CE$100,0)),0) | G3: ==IFERROR(SUMPRODUCT((ISNUMBER(SEARCH($B3,KeDa!$B$4:$B$100)))*(LEFT(TRIM(KeDa!$E$3:$CE$3),LEN(TRIM(G$2)))=TRIM(G$2))*IFERROR(KeDa!$E$4:$CE$100,0)),0)+IFERROR(SUMPRODUCT((ISNUMBER(SEARCH($B3,Tank!$B$4:$B$100)))*(LEFT(TRIM(Tank!$E$3:$CE$3),LEN(TRIM(G$2)))=TRIM(G$2))*IFERROR(Tank!$E$4:$CE$100,0)),0)+IFERROR(SUMPRODUCT((ISNUMBER(SEARCH($B3,Richard!$B$4:$B$100)))*(LEFT(TRIM(Richard!$E$3:$CE$3),LEN(TRIM(G$2)))=TRIM(G$2))*IFERROR(Richard!$E$4:$CE$100,0)),0)+IFERROR(SUMPRODUCT((ISNUMBER(SEARCH($B3,Jenny!$B$4:$B$100)))*(LEFT(TRIM(Jenny!$E$3:$CE$3),LEN(TRIM(G$2)))=TRIM(G$2))*IFERROR(Jenny!$E$4:$CE$100,0)),0)+IFERROR(SUMPRODUCT((ISNUMBER(SEARCH($B3,Cooper!$B$4:$B$100)))*(LEFT(TRIM(Cooper!$E$3:$CE$3),LEN(TRIM(G$2)))=TRIM(G$2))*IFERROR(Cooper!$E$4:$CE$100,0)),0)+IFERROR(SUMPRODUCT((ISNUMBER(SEARCH($B3,Summer!$B$4:$B$100)))*(LEFT(TRIM(Summer!$E$3:$CE$3),LEN(TRIM(G$2)))=TRIM(G$2))*IFERROR(Summer!$E$4:$CE$100,0)),0)+IFERROR(SUMPRODUCT((ISNUMBER(SEARCH($B3,Julie!$B$4:$B$100)))*(LEFT(TRIM(Julie!$E$3:$CE$3),LEN(TRIM(G$2)))=TRIM(G$2))*IFERROR(Julie!$E$4:$CE$100,0)),0)+IFERROR(SUMPRODUCT((ISNUMBER(SEARCH($B3,Jiao!$B$4:$B$100)))*(LEFT(TRIM(Jiao!$E$3:$CE$3),LEN(TRIM(G$2)))=TRIM(G$2))*IFERROR(Jiao!$E$4:$CE$100,0)),0) | H3: ==IFERROR(SUMPRODUCT((ISNUMBER(SEARCH($B3,KeDa!$B$4:$B$100)))*(LEFT(TRIM(KeDa!$E$3:$CE$3),LEN(TRIM(H$2)))=TRIM(H$2))*IFERROR(KeDa!$E$4:$CE$100,0)),0)+IFERROR(SUMPRODUCT((ISNUMBER(SEARCH($B3,Tank!$B$4:$B$100)))*(LEFT(TRIM(Tank!$E$3:$CE$3),LEN(TRIM(H$2)))=TRIM(H$2))*IFERROR(Tank!$E$4:$CE$100,0)),0)+IFERROR(SUMPRODUCT((ISNUMBER(SEARCH($B3,Richard!$B$4:$B$100)))*(LEFT(TRIM(Richard!$E$3:$CE$3),LEN(TRIM(H$2)))=TRIM(H$2))*IFERROR(Richard!$E$4:$CE$100,0)),0)+IFERROR(SUMPRODUCT((ISNUMBER(SEARCH($B3,Jenny!$B$4:$B$100)))*(LEFT(TRIM(Jenny!$E$3:$CE$3),LEN(TRIM(H$2)))=TRIM(H$2))*IFERROR(Jenny!$E$4:$CE$100,0)),0)+IFERROR(SUMPRODUCT((ISNUMBER(SEARCH($B3,Cooper!$B$4:$B$100)))*(LEFT(TRIM(Cooper!$E$3:$CE$3),LEN(TRIM(H$2)))=TRIM(H$2))*IFERROR(Cooper!$E$4:$CE$100,0)),0)+IFERROR(SUMPRODUCT((ISNUMBER(SEARCH($B3,Summer!$B$4:$B$100)))*(LEFT(TRIM(Summer!$E$3:$CE$3),LEN(TRIM(H$2)))=TRIM(H$2))*IFERROR(Summer!$E$4:$CE$100,0)),0)+IFERROR(SUMPRODUCT((ISNUMBER(SEARCH($B3,Julie!$B$4:$B$100)))*(LEFT(TRIM(Julie!$E$3:$CE$3),LEN(TRIM(H$2)))=TRIM(H$2))*IFERROR(Julie!$E$4:$CE$100,0)),0)+IFERROR(SUMPRODUCT((ISNUMBER(SEARCH($B3,Jiao!$B$4:$B$100)))*(LEFT(TRIM(Jiao!$E$3:$CE$3),LEN(TRIM(H$2)))=TRIM(H$2))*IFERROR(Jiao!$E$4:$CE$100,0)),0) | I3: ==IFERROR(SUMPRODUCT((ISNUMBER(SEARCH($B3,KeDa!$B$4:$B$100)))*(LEFT(TRIM(KeDa!$E$3:$CE$3),LEN(TRIM(I$2)))=TRIM(I$2))*IFERROR(KeDa!$E$4:$CE$100,0)),0)+IFERROR(SUMPRODUCT((ISNUMBER(SEARCH($B3,Tank!$B$4:$B$100)))*(LEFT(TRIM(Tank!$E$3:$CE$3),LEN(TRIM(I$2)))=TRIM(I$2))*IFERROR(Tank!$E$4:$CE$100,0)),0)+IFERROR(SUMPRODUCT((ISNUMBER(SEARCH($B3,Richard!$B$4:$B$100)))*(LEFT(TRIM(Richard!$E$3:$CE$3),LEN(TRIM(I$2)))=TRIM(I$2))*IFERROR(Richard!$E$4:$CE$100,0)),0)+IFERROR(SUMPRODUCT((ISNUMBER(SEARCH($B3,Jenny!$B$4:$B$100)))*(LEFT(TRIM(Jenny!$E$3:$CE$3),LEN(TRIM(I$2)))=TRIM(I$2))*IFERROR(Jenny!$E$4:$CE$100,0)),0)+IFERROR(SUMPRODUCT((ISNUMBER(SEARCH($B3,Cooper!$B$4:$B$100)))*(LEFT(TRIM(Cooper!$E$3:$CE$3),LEN(TRIM(I$2)))=TRIM(I$2))*IFERROR(Cooper!$E$4:$CE$100,0)),0)+IFERROR(SUMPRODUCT((ISNUMBER(SEARCH($B3,Summer!$B$4:$B$100)))*(LEFT(TRIM(Summer!$E$3:$CE$3),LEN(TRIM(I$2)))=TRIM(I$2))*IFERROR(Summer!$E$4:$CE$100,0)),0)+IFERROR(SUMPRODUCT((ISNUMBER(SEARCH($B3,Julie!$B$4:$B$100)))*(LEFT(TRIM(Julie!$E$3:$CE$3),LEN(TRIM(I$2)))=TRIM(I$2))*IFERROR(Julie!$E$4:$CE$100,0)),0)+IFERROR(SUMPRODUCT((ISNUMBER(SEARCH($B3,Jiao!$B$4:$B$100)))*(LEFT(TRIM(Jiao!$E$3:$CE$3),LEN(TRIM(I$2)))=TRIM(I$2))*IFERROR(Jiao!$E$4:$CE$100,0)),0) | J3: ==IFERROR(SUMPRODUCT((ISNUMBER(SEARCH($B3,KeDa!$B$4:$B$100)))*(LEFT(TRIM(KeDa!$E$3:$CE$3),LEN(TRIM(J$2)))=TRIM(J$2))*IFERROR(KeDa!$E$4:$CE$100,0)),0)+IFERROR(SUMPRODUCT((ISNUMBER(SEARCH($B3,Tank!$B$4:$B$100)))*(LEFT(TRIM(Tank!$E$3:$CE$3),LEN(TRIM(J$2)))=TRIM(J$2))*IFERROR(Tank!$E$4:$CE$100,0)),0)+IFERROR(SUMPRODUCT((ISNUMBER(SEARCH($B3,Richard!$B$4:$B$100)))*(LEFT(TRIM(Richard!$E$3:$CE$3),LEN(TRIM(J$2)))=TRIM(J$2))*IFERROR(Richard!$E$4:$CE$100,0)),0)+IFERROR(SUMPRODUCT((ISNUMBER(SEARCH($B3,Jenny!$B$4:$B$100)))*(LEFT(TRIM(Jenny!$E$3:$CE$3),LEN(TRIM(J$2)))=TRIM(J$2))*IFERROR(Jenny!$E$4:$CE$100,0)),0)+IFERROR(SUMPRODUCT((ISNUMBER(SEARCH($B3,Cooper!$B$4:$B$100)))*(LEFT(TRIM(Cooper!$E$3:$CE$3),LEN(TRIM(J$2)))=TRIM(J$2))*IFERROR(Cooper!$E$4:$CE$100,0)),0)+IFERROR(SUMPRODUCT((ISNUMBER(SEARCH($B3,Summer!$B$4:$B$100)))*(LEFT(TRIM(Summer!$E$3:$CE$3),LEN(TRIM(J$2)))=TRIM(J$2))*IFERROR(Summer!$E$4:$CE$100,0)),0)+IFERROR(SUMPRODUCT((ISNUMBER(SEARCH($B3,Julie!$B$4:$B$100)))*(LEFT(TRIM(Julie!$E$3:$CE$3),LEN(TRIM(J$2)))=TRIM(J$2))*IFERROR(Julie!$E$4:$CE$100,0)),0)+IFERROR(SUMPRODUCT((ISNUMBER(SEARCH($B3,Jiao!$B$4:$B$100)))*(LEFT(TRIM(Jiao!$E$3:$CE$3),LEN(TRIM(J$2)))=TRIM(J$2))*IFERROR(Jiao!$E$4:$CE$100,0)),0) | K3: ==IFERROR(SUMPRODUCT((ISNUMBER(SEARCH($B3,KeDa!$B$4:$B$100)))*(LEFT(TRIM(KeDa!$E$3:$CE$3),LEN(TRIM(K$2)))=TRIM(K$2))*IFERROR(KeDa!$E$4:$CE$100,0)),0)+IFERROR(SUMPRODUCT((ISNUMBER(SEARCH($B3,Tank!$B$4:$B$100)))*(LEFT(TRIM(Tank!$E$3:$CE$3),LEN(TRIM(K$2)))=TRIM(K$2))*IFERROR(Tank!$E$4:$CE$100,0)),0)+IFERROR(SUMPRODUCT((ISNUMBER(SEARCH($B3,Richard!$B$4:$B$100)))*(LEFT(TRIM(Richard!$E$3:$CE$3),LEN(TRIM(K$2)))=TRIM(K$2))*IFERROR(Richard!$E$4:$CE$100,0)),0)+IFERROR(SUMPRODUCT((ISNUMBER(SEARCH($B3,Jenny!$B$4:$B$100)))*(LEFT(TRIM(Jenny!$E$3:$CE$3),LEN(TRIM(K$2)))=TRIM(K$2))*IFERROR(Jenny!$E$4:$CE$100,0)),0)+IFERROR(SUMPRODUCT((ISNUMBER(SEARCH($B3,Cooper!$B$4:$B$100)))*(LEFT(TRIM(Cooper!$E$3:$CE$3),LEN(TRIM(K$2)))=TRIM(K$2))*IFERROR(Cooper!$E$4:$CE$100,0)),0)+IFERROR(SUMPRODUCT((ISNUMBER(SEARCH($B3,Summer!$B$4:$B$100)))*(LEFT(TRIM(Summer!$E$3:$CE$3),LEN(TRIM(K$2)))=TRIM(K$2))*IFERROR(Summer!$E$4:$CE$100,0)),0)+IFERROR(SUMPRODUCT((ISNUMBER(SEARCH($B3,Julie!$B$4:$B$100)))*(LEFT(TRIM(Julie!$E$3:$CE$3),LEN(TRIM(K$2)))=TRIM(K$2))*IFERROR(Julie!$E$4:$CE$100,0)),0)+IFERROR(SUMPRODUCT((ISNUMBER(SEARCH($B3,Jiao!$B$4:$B$100)))*(LEFT(TRIM(Jiao!$E$3:$CE$3),LEN(TRIM(K$2)))=TRIM(K$2))*IFERROR(Jiao!$E$4:$CE$100,0)),0)
A4: 2 | B4: 朱航舟 Tim | C4: G6 | D4: Tesla | E4: ==IFERROR(SUMPRODUCT((ISNUMBER(SEARCH($B4,KeDa!$B$4:$B$100)))*(LEFT(TRIM(KeDa!$E$3:$CE$3),LEN(TRIM(E$2)))=TRIM(E$2))*IFERROR(KeDa!$E$4:$CE$100,0)),0)+IFERROR(SUMPRODUCT((ISNUMBER(SEARCH($B4,Tank!$B$4:$B$100)))*(LEFT(TRIM(Tank!$E$3:$CE$3),LEN(TRIM(E$2)))=TRIM(E$2))*IFERROR(Tank!$E$4:$CE$100,0)),0)+IFERROR(SUMPRODUCT((ISNUMBER(SEARCH($B4,Richard!$B$4:$B$100)))*(LEFT(TRIM(Richard!$E$3:$CE$3),LEN(TRIM(E$2)))=TRIM(E$2))*IFERROR(Richard!$E$4:$CE$100,0)),0)+IFERROR(SUMPRODUCT((ISNUMBER(SEARCH($B4,Jenny!$B$4:$B$100)))*(LEFT(TRIM(Jenny!$E$3:$CE$3),LEN(TRIM(E$2)))=TRIM(E$2))*IFERROR(Jenny!$E$4:$CE$100,0)),0)+IFERROR(SUMPRODUCT((ISNUMBER(SEARCH($B4,Cooper!$B$4:$B$100)))*(LEFT(TRIM(Cooper!$E$3:$CE$3),LEN(TRIM(E$2)))=TRIM(E$2))*IFERROR(Cooper!$E$4:$CE$100,0)),0)+IFERROR(SUMPRODUCT((ISNUMBER(SEARCH($B4,Summer!$B$4:$B$100)))*(LEFT(TRIM(Summer!$E$3:$CE$3),LEN(TRIM(E$2)))=TRIM(E$2))*IFERROR(Summer!$E$4:$CE$100,0)),0)+IFERROR(SUMPRODUCT((ISNUMBER(SEARCH($B4,Julie!$B$4:$B$100)))*(LEFT(TRIM(Julie!$E$3:$CE$3),LEN(TRIM(E$2)))=TRIM(E$2))*IFERROR(Julie!$E$4:$CE$100,0)),0)+IFERROR(SUMPRODUCT((ISNUMBER(SEARCH($B4,Jiao!$B$4:$B$100)))*(LEFT(TRIM(Jiao!$E$3:$CE$3),LEN(TRIM(E$2)))=TRIM(E$2))*IFERROR(Jiao!$E$4:$CE$100,0)),0) | F4: ==IFERROR(SUMPRODUCT((ISNUMBER(SEARCH($B4,KeDa!$B$4:$B$100)))*(LEFT(TRIM(KeDa!$E$3:$CE$3),LEN(TRIM(F$2)))=TRIM(F$2))*IFERROR(KeDa!$E$4:$CE$100,0)),0)+IFERROR(SUMPRODUCT((ISNUMBER(SEARCH($B4,Tank!$B$4:$B$100)))*(LEFT(TRIM(Tank!$E$3:$CE$3),LEN(TRIM(F$2)))=TRIM(F$2))*IFERROR(Tank!$E$4:$CE$100,0)),0)+IFERROR(SUMPRODUCT((ISNUMBER(SEARCH($B4,Richard!$B$4:$B$100)))*(LEFT(TRIM(Richard!$E$3:$CE$3),LEN(TRIM(F$2)))=TRIM(F$2))*IFERROR(Richard!$E$4:$CE$100,0)),0)+IFERROR(SUMPRODUCT((ISNUMBER(SEARCH($B4,Jenny!$B$4:$B$100)))*(LEFT(TRIM(Jenny!$E$3:$CE$3),LEN(TRIM(F$2)))=TRIM(F$2))*IFERROR(Jenny!$E$4:$CE$100,0)),0)+IFERROR(SUMPRODUCT((ISNUMBER(SEARCH($B4,Cooper!$B$4:$B$100)))*(LEFT(TRIM(Cooper!$E$3:$CE$3),LEN(TRIM(F$2)))=TRIM(F$2))*IFERROR(Cooper!$E$4:$CE$100,0)),0)+IFERROR(SUMPRODUCT((ISNUMBER(SEARCH($B4,Summer!$B$4:$B$100)))*(LEFT(TRIM(Summer!$E$3:$CE$3),LEN(TRIM(F$2)))=TRIM(F$2))*IFERROR(Summer!$E$4:$CE$100,0)),0)+IFERROR(SUMPRODUCT((ISNUMBER(SEARCH($B4,Julie!$B$4:$B$100)))*(LEFT(TRIM(Julie!$E$3:$CE$3),LEN(TRIM(F$2)))=TRIM(F$2))*IFERROR(Julie!$E$4:$CE$100,0)),0)+IFERROR(SUMPRODUCT((ISNUMBER(SEARCH($B4,Jiao!$B$4:$B$100)))*(LEFT(TRIM(Jiao!$E$3:$CE$3),LEN(TRIM(F$2)))=TRIM(F$2))*IFERROR(Jiao!$E$4:$CE$100,0)),0) | G4: ==IFERROR(SUMPRODUCT((ISNUMBER(SEARCH($B4,KeDa!$B$4:$B$100)))*(LEFT(TRIM(KeDa!$E$3:$CE$3),LEN(TRIM(G$2)))=TRIM(G$2))*IFERROR(KeDa!$E$4:$CE$100,0)),0)+IFERROR(SUMPRODUCT((ISNUMBER(SEARCH($B4,Tank!$B$4:$B$100)))*(LEFT(TRIM(Tank!$E$3:$CE$3),LEN(TRIM(G$2)))=TRIM(G$2))*IFERROR(Tank!$E$4:$CE$100,0)),0)+IFERROR(SUMPRODUCT((ISNUMBER(SEARCH($B4,Richard!$B$4:$B$100)))*(LEFT(TRIM(Richard!$E$3:$CE$3),LEN(TRIM(G$2)))=TRIM(G$2))*IFERROR(Richard!$E$4:$CE$100,0)),0)+IFERROR(SUMPRODUCT((ISNUMBER(SEARCH($B4,Jenny!$B$4:$B$100)))*(LEFT(TRIM(Jenny!$E$3:$CE$3),LEN(TRIM(G$2)))=TRIM(G$2))*IFERROR(Jenny!$E$4:$CE$100,0)),0)+IFERROR(SUMPRODUCT((ISNUMBER(SEARCH($B4,Cooper!$B$4:$B$100)))*(LEFT(TRIM(Cooper!$E$3:$CE$3),LEN(TRIM(G$2)))=TRIM(G$2))*IFERROR(Cooper!$E$4:$CE$100,0)),0)+IFERROR(SUMPRODUCT((ISNUMBER(SEARCH($B4,Summer!$B$4:$B$100)))*(LEFT(TRIM(Summer!$E$3:$CE$3),LEN(TRIM(G$2)))=TRIM(G$2))*IFERROR(Summer!$E$4:$CE$100,0)),0)+IFERROR(SUMPRODUCT((ISNUMBER(SEARCH($B4,Julie!$B$4:$B$100)))*(LEFT(TRIM(Julie!$E$3:$CE$3),LEN(TRIM(G$2)))=TRIM(G$2))*IFERROR(Julie!$E$4:$CE$100,0)),0)+IFERROR(SUMPRODUCT((ISNUMBER(SEARCH($B4,Jiao!$B$4:$B$100)))*(LEFT(TRIM(Jiao!$E$3:$CE$3),LEN(TRIM(G$2)))=TRIM(G$2))*IFERROR(Jiao!$E$4:$CE$100,0)),0) | H4: ==IFERROR(SUMPRODUCT((ISNUMBER(SEARCH($B4,KeDa!$B$4:$B$100)))*(LEFT(TRIM(KeDa!$E$3:$CE$3),LEN(TRIM(H$2)))=TRIM(H$2))*IFERROR(KeDa!$E$4:$CE$100,0)),0)+IFERROR(SUMPRODUCT((ISNUMBER(SEARCH($B4,Tank!$B$4:$B$100)))*(LEFT(TRIM(Tank!$E$3:$CE$3),LEN(TRIM(H$2)))=TRIM(H$2))*IFERROR(Tank!$E$4:$CE$100,0)),0)+IFERROR(SUMPRODUCT((ISNUMBER(SEARCH($B4,Richard!$B$4:$B$100)))*(LEFT(TRIM(Richard!$E$3:$CE$3),LEN(TRIM(H$2)))=TRIM(H$2))*IFERROR(Richard!$E$4:$CE$100,0)),0)+IFERROR(SUMPRODUCT((ISNUMBER(SEARCH($B4,Jenny!$B$4:$B$100)))*(LEFT(TRIM(Jenny!$E$3:$CE$3),LEN(TRIM(H$2)))=TRIM(H$2))*IFERROR(Jenny!$E$4:$CE$100,0)),0)+IFERROR(SUMPRODUCT((ISNUMBER(SEARCH($B4,Cooper!$B$4:$B$100)))*(LEFT(TRIM(Cooper!$E$3:$CE$3),LEN(TRIM(H$2)))=TRIM(H$2))*IFERROR(Cooper!$E$4:$CE$100,0)),0)+IFERROR(SUMPRODUCT((ISNUMBER(SEARCH($B4,Summer!$B$4:$B$100)))*(LEFT(TRIM(Summer!$E$3:$CE$3),LEN(TRIM(H$2)))=TRIM(H$2))*IFERROR(Summer!$E$4:$CE$100,0)),0)+IFERROR(SUMPRODUCT((ISNUMBER(SEARCH($B4,Julie!$B$4:$B$100)))*(LEFT(TRIM(Julie!$E$3:$CE$3),LEN(TRIM(H$2)))=TRIM(H$2))*IFERROR(Julie!$E$4:$CE$100,0)),0)+IFERROR(SUMPRODUCT((ISNUMBER(SEARCH($B4,Jiao!$B$4:$B$100)))*(LEFT(TRIM(Jiao!$E$3:$CE$3),LEN(TRIM(H$2)))=TRIM(H$2))*IFERROR(Jiao!$E$4:$CE$100,0)),0) | I4: ==IFERROR(SUMPRODUCT((ISNUMBER(SEARCH($B4,KeDa!$B$4:$B$100)))*(LEFT(TRIM(KeDa!$E$3:$CE$3),LEN(TRIM(I$2)))=TRIM(I$2))*IFERROR(KeDa!$E$4:$CE$100,0)),0)+IFERROR(SUMPRODUCT((ISNUMBER(SEARCH($B4,Tank!$B$4:$B$100)))*(LEFT(TRIM(Tank!$E$3:$CE$3),LEN(TRIM(I$2)))=TRIM(I$2))*IFERROR(Tank!$E$4:$CE$100,0)),0)+IFERROR(SUMPRODUCT((ISNUMBER(SEARCH($B4,Richard!$B$4:$B$100)))*(LEFT(TRIM(Richard!$E$3:$CE$3),LEN(TRIM(I$2)))=TRIM(I$2))*IFERROR(Richard!$E$4:$CE$100,0)),0)+IFERROR(SUMPRODUCT((ISNUMBER(SEARCH($B4,Jenny!$B$4:$B$100)))*(LEFT(TRIM(Jenny!$E$3:$CE$3),LEN(TRIM(I$2)))=TRIM(I$2))*IFERROR(Jenny!$E$4:$CE$100,0)),0)+IFERROR(SUMPRODUCT((ISNUMBER(SEARCH($B4,Cooper!$B$4:$B$100)))*(LEFT(TRIM(Cooper!$E$3:$CE$3),LEN(TRIM(I$2)))=TRIM(I$2))*IFERROR(Cooper!$E$4:$CE$100,0)),0)+IFERROR(SUMPRODUCT((ISNUMBER(SEARCH($B4,Summer!$B$4:$B$100)))*(LEFT(TRIM(Summer!$E$3:$CE$3),LEN(TRIM(I$2)))=TRIM(I$2))*IFERROR(Summer!$E$4:$CE$100,0)),0)+IFERROR(SUMPRODUCT((ISNUMBER(SEARCH($B4,Julie!$B$4:$B$100)))*(LEFT(TRIM(Julie!$E$3:$CE$3),LEN(TRIM(I$2)))=TRIM(I$2))*IFERROR(Julie!$E$4:$CE$100,0)),0)+IFERROR(SUMPRODUCT((ISNUMBER(SEARCH($B4,Jiao!$B$4:$B$100)))*(LEFT(TRIM(Jiao!$E$3:$CE$3),LEN(TRIM(I$2)))=TRIM(I$2))*IFERROR(Jiao!$E$4:$CE$100,0)),0) | J4: ==IFERROR(SUMPRODUCT((ISNUMBER(SEARCH($B4,KeDa!$B$4:$B$100)))*(LEFT(TRIM(KeDa!$E$3:$CE$3),LEN(TRIM(J$2)))=TRIM(J$2))*IFERROR(KeDa!$E$4:$CE$100,0)),0)+IFERROR(SUMPRODUCT((ISNUMBER(SEARCH($B4,Tank!$B$4:$B$100)))*(LEFT(TRIM(Tank!$E$3:$CE$3),LEN(TRIM(J$2)))=TRIM(J$2))*IFERROR(Tank!$E$4:$CE$100,0)),0)+IFERROR(SUMPRODUCT((ISNUMBER(SEARCH($B4,Richard!$B$4:$B$100)))*(LEFT(TRIM(Richard!$E$3:$CE$3),LEN(TRIM(J$2)))=TRIM(J$2))*IFERROR(Richard!$E$4:$CE$100,0)),0)+IFERROR(SUMPRODUCT((ISNUMBER(SEARCH($B4,Jenny!$B$4:$B$100)))*(LEFT(TRIM(Jenny!$E$3:$CE$3),LEN(TRIM(J$2)))=TRIM(J$2))*IFERROR(Jenny!$E$4:$CE$100,0)),0)+IFERROR(SUMPRODUCT((ISNUMBER(SEARCH($B4,Cooper!$B$4:$B$100)))*(LEFT(TRIM(Cooper!$E$3:$CE$3),LEN(TRIM(J$2)))=TRIM(J$2))*IFERROR(Cooper!$E$4:$CE$100,0)),0)+IFERROR(SUMPRODUCT((ISNUMBER(SEARCH($B4,Summer!$B$4:$B$100)))*(LEFT(TRIM(Summer!$E$3:$CE$3),LEN(TRIM(J$2)))=TRIM(J$2))*IFERROR(Summer!$E$4:$CE$100,0)),0)+IFERROR(SUMPRODUCT((ISNUMBER(SEARCH($B4,Julie!$B$4:$B$100)))*(LEFT(TRIM(Julie!$E$3:$CE$3),LEN(TRIM(J$2)))=TRIM(J$2))*IFERROR(Julie!$E$4:$CE$100,0)),0)+IFERROR(SUMPRODUCT((ISNUMBER(SEARCH($B4,Jiao!$B$4:$B$100)))*(LEFT(TRIM(Jiao!$E$3:$CE$3),LEN(TRIM(J$2)))=TRIM(J$2))*IFERROR(Jiao!$E$4:$CE$100,0)),0) | K4: ==IFERROR(SUMPRODUCT((ISNUMBER(SEARCH($B4,KeDa!$B$4:$B$100)))*(LEFT(TRIM(KeDa!$E$3:$CE$3),LEN(TRIM(K$2)))=TRIM(K$2))*IFERROR(KeDa!$E$4:$CE$100,0)),0)+IFERROR(SUMPRODUCT((ISNUMBER(SEARCH($B4,Tank!$B$4:$B$100)))*(LEFT(TRIM(Tank!$E$3:$CE$3),LEN(TRIM(K$2)))=TRIM(K$2))*IFERROR(Tank!$E$4:$CE$100,0)),0)+IFERROR(SUMPRODUCT((ISNUMBER(SEARCH($B4,Richard!$B$4:$B$100)))*(LEFT(TRIM(Richard!$E$3:$CE$3),LEN(TRIM(K$2)))=TRIM(K$2))*IFERROR(Richard!$E$4:$CE$100,0)),0)+IFERROR(SUMPRODUCT((ISNUMBER(SEARCH($B4,Jenny!$B$4:$B$100)))*(LEFT(TRIM(Jenny!$E$3:$CE$3),LEN(TRIM(K$2)))=TRIM(K$2))*IFERROR(Jenny!$E$4:$CE$100,0)),0)+IFERROR(SUMPRODUCT((ISNUMBER(SEARCH($B4,Cooper!$B$4:$B$100)))*(LEFT(TRIM(Cooper!$E$3:$CE$3),LEN(TRIM(K$2)))=TRIM(K$2))*IFERROR(Cooper!$E$4:$CE$100,0)),0)+IFERROR(SUMPRODUCT((ISNUMBER(SEARCH($B4,Summer!$B$4:$B$100)))*(LEFT(TRIM(Summer!$E$3:$CE$3),LEN(TRIM(K$2)))=TRIM(K$2))*IFERROR(Summer!$E$4:$CE$100,0)),0)+IFERROR(SUMPRODUCT((ISNUMBER(SEARCH($B4,Julie!$B$4:$B$100)))*(LEFT(TRIM(Julie!$E$3:$CE$3),LEN(TRIM(K$2)))=TRIM(K$2))*IFERROR(Julie!$E$4:$CE$100,0)),0)+IFERROR(SUMPRODUCT((ISNUMBER(SEARCH($B4,Jiao!$B$4:$B$100)))*(LEFT(TRIM(Jiao!$E$3:$CE$3),LEN(TRIM(K$2)))=TRIM(K$2))*IFERROR(Jiao!$E$4:$CE$100,0)),0)
